Workbook

Sheet compiled grading
A1: persona type | B1: transcript number | C1: grader name | D1: 1.1.A | E1: 1.1.B | F1: 1.1.C | G1: 1.2.A | H1: 1.2.B | I1: 1.3.A | J1: 1.3.B | K1: 1.3.C | L1: 2.1.A | M1: 2.2.A | N1: 2.2.B | O1: 3.1.A | P1: 3.2.A | Q1: 3.2.B | R1: total score
A2: cooperative | B2: 123 | C2: faizan | D2: =IF($C2="faizan",SUMIFS('faizan grading'!D:D,'faizan grading'!$A:$A,$A2,'faizan grading'!$B:$B,$B2),IF($C2="romain",SUMIFS('romain grading'!D:D,'romain grading'!$A:$A,$A2,'romain grading'!$B:$B,$B2),SUMIFS('nishita grading'!D:D,'nishita grading'!$A:$A,$A2,'nishita grading'!$B:$B,$B2))) | E2: =IF($C2="faizan",SUMIFS('faizan grading'!E:E,'faizan grading'!$A:$A,$A2,'faizan grading'!$B:$B,$B2),IF($C2="romain",SUMIFS('romain grading'!E:E,'romain grading'!$A:$A,$A2,'romain grading'!$B:$B,$B2),SUMIFS('nishita grading'!E:E,'nishita grading'!$A:$A,$A2,'nishita grading'!$B:$B,$B2))) | F2: =IF($C2="faizan",SUMIFS('faizan grading'!F:F,'faizan grading'!$A:$A,$A2,'faizan grading'!$B:$B,$B2),IF($C2="romain",SUMIFS('romain grading'!F:F,'romain grading'!$A:$A,$A2,'romain grading'!$B:$B,$B2),SUMIFS('nishita grading'!F:F,'nishita grading'!$A:$A,$A2,'nishita grading'!$B:$B,$B2))) | G2: =IF($C2="faizan",SUMIFS('faizan grading'!G:G,'faizan grading'!$A:$A,$A2,'faizan grading'!$B:$B,$B2),IF($C2="romain",SUMIFS('romain grading'!G:G,'romain grading'!$A:$A,$A2,'romain grading'!$B:$B,$B2),SUMIFS('nishita grading'!G:G,'nishita grading'!$A:$A,$A2,'nishita grading'!$B:$B,$B2))) | H2: =IF($C2="faizan",SUMIFS('faizan grading'!H:H,'faizan grading'!$A:$A,$A2,'faizan grading'!$B:$B,$B2),IF($C2="romain",SUMIFS('romain grading'!H:H,'romain grading'!$A:$A,$A2,'romain grading'!$B:$B,$B2),SUMIFS('nishita grading'!H:H,'nishita grading'!$A:$A,$A2,'nishita grading'!$B:$B,$B2))) | I2: =IF($C2="faizan",SUMIFS('faizan grading'!I:I,'faizan grading'!$A:$A,$A2,'faizan grading'!$B:$B,$B2),IF($C2="romain",SUMIFS('romain grading'!I:I,'romain grading'!$A:$A,$A2,'romain grading'!$B:$B,$B2),SUMIFS('nishita grading'!I:I,'nishita grading'!$A:$A,$A2,'nishita grading'!$B:$B,$B2))) | J2: =IF($C2="faizan",SUMIFS('faizan grading'!J:J,'faizan grading'!$A:$A,$A2,'faizan grading'!$B:$B,$B2),IF($C2="romain",SUMIFS('romain grading'!J:J,'romain grading'!$A:$A,$A2,'romain grading'!$B:$B,$B2),SUMIFS('nishita grading'!J:J,'nishita grading'!$A:$A,$A2,'nishita grading'!$B:$B,$B2))) | K2: =IF($C2="faizan",SUMIFS('faizan grading'!K:K,'faizan grading'!$A:$A,$A2,'faizan grading'!$B:$B,$B2),IF($C2="romain",SUMIFS('romain grading'!K:K,'romain grading'!$A:$A,$A2,'romain grading'!$B:$B,$B2),SUMIFS('nishita grading'!K:K,'nishita grading'!$A:$A,$A2,'nishita grading'!$B:$B,$B2))) | L2: =IF($C2="faizan",SUMIFS('faizan grading'!L:L,'faizan grading'!$A:$A,$A2,'faizan grading'!$B:$B,$B2),IF($C2="romain",SUMIFS('romain grading'!L:L,'romain grading'!$A:$A,$A2,'romain grading'!$B:$B,$B2),SUMIFS('nishita grading'!L:L,'nishita grading'!$A:$A,$A2,'nishita grading'!$B:$B,$B2))) | M2: =IF($C2="faizan",SUMIFS('faizan grading'!M:M,'faizan grading'!$A:$A,$A2,'faizan grading'!$B:$B,$B2),IF($C2="romain",SUMIFS('romain grading'!M:M,'romain grading'!$A:$A,$A2,'romain grading'!$B:$B,$B2),SUMIFS('nishita grading'!M:M,'nishita grading'!$A:$A,$A2,'nishita grading'!$B:$B,$B2))) | N2: =IF($C2="faizan",SUMIFS('faizan grading'!N:N,'faizan grading'!$A:$A,$A2,'faizan grading'!$B:$B,$B2),IF($C2="romain",SUMIFS('romain grading'!N:N,'romain grading'!$A:$A,$A2,'romain grading'!$B:$B,$B2),SUMIFS('nishita grading'!N:N,'nishita grading'!$A:$A,$A2,'nishita grading'!$B:$B,$B2))) | O2: =IF($C2="faizan",SUMIFS('faizan grading'!O:O,'faizan grading'!$A:$A,$A2,'faizan grading'!$B:$B,$B2),IF($C2="romain",SUMIFS('romain grading'!O:O,'romain grading'!$A:$A,$A2,'romain grading'!$B:$B,$B2),SUMIFS('nishita grading'!O:O,'nishita grading'!$A:$A,$A2,'nishita grading'!$B:$B,$B2))) | P2: =IF($C2="faizan",SUMIFS('faizan grading'!P:P,'faizan grading'!$A:$A,$A2,'faizan grading'!$B:$B,$B2),IF($C2="romain",SUMIFS('romain grading'!P:P,'romain grading'!$A:$A,$A2,'romain grading'!$B:$B,$B2),SUMIFS('nishita grading'!P:P,'nishita grading'!$A:$A,$A2,'nishita grading'!$B:$B,$B2))) | Q2: =IF($C2="faizan",SUMIFS('faizan grading'!Q:Q,'faizan grading'!$A:$A,$A2,'faizan grading'!$B:$B,$B2),IF($C2="romain",SUMIFS('romain grading'!Q:Q,'romain grading'!$A:$A,$A2,'romain grading'!$B:$B,$B2),SUMIFS('nishita grading'!Q:Q,'nishita grading'!$A:$A,$A2,'nishita grading'!$B:$B,$B2))) | R2: =44-SUM(D2:Q2)
A3: cooperative | B3: 123 | C3: romain | D3: =IF($C3="faizan",SUMIFS('faizan grading'!D:D,'faizan grading'!$A:$A,$A3,'faizan grading'!$B:$B,$B3),IF($C3="romain",SUMIFS('romain grading'!D:D,'romain grading'!$A:$A,$A3,'romain grading'!$B:$B,$B3),SUMIFS('nishita grading'!D:D,'nishita grading'!$A:$A,$A3,'nishita grading'!$B:$B,$B3))) | E3: =IF($C3="faizan",SUMIFS('faizan grading'!E:E,'faizan grading'!$A:$A,$A3,'faizan grading'!$B:$B,$B3),IF($C3="romain",SUMIFS('romain grading'!E:E,'romain grading'!$A:$A,$A3,'romain grading'!$B:$B,$B3),SUMIFS('nishita grading'!E:E,'nishita grading'!$A:$A,$A3,'nishita grading'!$B:$B,$B3))) | F3: =IF($C3="faizan",SUMIFS('faizan grading'!F:F,'faizan grading'!$A:$A,$A3,'faizan grading'!$B:$B,$B3),IF($C3="romain",SUMIFS('romain grading'!F:F,'romain grading'!$A:$A,$A3,'romain grading'!$B:$B,$B3),SUMIFS('nishita grading'!F:F,'nishita grading'!$A:$A,$A3,'nishita grading'!$B:$B,$B3))) | G3: =IF($C3="faizan",SUMIFS('faizan grading'!G:G,'faizan grading'!$A:$A,$A3,'faizan grading'!$B:$B,$B3),IF($C3="romain",SUMIFS('romain grading'!G:G,'romain grading'!$A:$A,$A3,'romain grading'!$B:$B,$B3),SUMIFS('nishita grading'!G:G,'nishita grading'!$A:$A,$A3,'nishita grading'!$B:$B,$B3))) | H3: =IF($C3="faizan",SUMIFS('faizan grading'!H:H,'faizan grading'!$A:$A,$A3,'faizan grading'!$B:$B,$B3),IF($C3="romain",SUMIFS('romain grading'!H:H,'romain grading'!$A:$A,$A3,'romain grading'!$B:$B,$B3),SUMIFS('nishita grading'!H:H,'nishita grading'!$A:$A,$A3,'nishita grading'!$B:$B,$B3))) | I3: =IF($C3="faizan",SUMIFS('faizan grading'!I:I,'faizan grading'!$A:$A,$A3,'faizan grading'!$B:$B,$B3),IF($C3="romain",SUMIFS('romain grading'!I:I,'romain grading'!$A:$A,$A3,'romain grading'!$B:$B,$B3),SUMIFS('nishita grading'!I:I,'nishita grading'!$A:$A,$A3,'nishita grading'!$B:$B,$B3))) | J3: =IF($C3="faizan",SUMIFS('faizan grading'!J:J,'faizan grading'!$A:$A,$A3,'faizan grading'!$B:$B,$B3),IF($C3="romain",SUMIFS('romain grading'!J:J,'romain grading'!$A:$A,$A3,'romain grading'!$B:$B,$B3),SUMIFS('nishita grading'!J:J,'nishita grading'!$A:$A,$A3,'nishita grading'!$B:$B,$B3))) | K3: =IF($C3="faizan",SUMIFS('faizan grading'!K:K,'faizan grading'!$A:$A,$A3,'faizan grading'!$B:$B,$B3),IF($C3="romain",SUMIFS('romain grading'!K:K,'romain grading'!$A:$A,$A3,'romain grading'!$B:$B,$B3),SUMIFS('nishita grading'!K:K,'nishita grading'!$A:$A,$A3,'nishita grading'!$B:$B,$B3))) | L3: =IF($C3="faizan",SUMIFS('faizan grading'!L:L,'faizan grading'!$A:$A,$A3,'faizan grading'!$B:$B,$B3),IF($C3="romain",SUMIFS('romain grading'!L:L,'romain grading'!$A:$A,$A3,'romain grading'!$B:$B,$B3),SUMIFS('nishita grading'!L:L,'nishita grading'!$A:$A,$A3,'nishita grading'!$B:$B,$B3))) | M3: =IF($C3="faizan",SUMIFS('faizan grading'!M:M,'faizan grading'!$A:$A,$A3,'faizan grading'!$B:$B,$B3),IF($C3="romain",SUMIFS('romain grading'!M:M,'romain grading'!$A:$A,$A3,'romain grading'!$B:$B,$B3),SUMIFS('nishita grading'!M:M,'nishita grading'!$A:$A,$A3,'nishita grading'!$B:$B,$B3))) | N3: =IF($C3="faizan",SUMIFS('faizan grading'!N:N,'faizan grading'!$A:$A,$A3,'faizan grading'!$B:$B,$B3),IF($C3="romain",SUMIFS('romain grading'!N:N,'romain grading'!$A:$A,$A3,'romain grading'!$B:$B,$B3),SUMIFS('nishita grading'!N:N,'nishita grading'!$A:$A,$A3,'nishita grading'!$B:$B,$B3))) | O3: =IF($C3="faizan",SUMIFS('faizan grading'!O:O,'faizan grading'!$A:$A,$A3,'faizan grading'!$B:$B,$B3),IF($C3="romain",SUMIFS('romain grading'!O:O,'romain grading'!$A:$A,$A3,'romain grading'!$B:$B,$B3),SUMIFS('nishita grading'!O:O,'nishita grading'!$A:$A,$A3,'nishita grading'!$B:$B,$B3))) | P3: =IF($C3="faizan",SUMIFS('faizan grading'!P:P,'faizan grading'!$A:$A,$A3,'faizan grading'!$B:$B,$B3),IF($C3="romain",SUMIFS('romain grading'!P:P,'romain grading'!$A:$A,$A3,'romain grading'!$B:$B,$B3),SUMIFS('nishita grading'!P:P,'nishita grading'!$A:$A,$A3,'nishita grading'!$B:$B,$B3))) | Q3: =IF($C3="faizan",SUMIFS('faizan grading'!Q:Q,'faizan grading'!$A:$A,$A3,'faizan grading'!$B:$B,$B3),IF($C3="romain",SUMIFS('romain grading'!Q:Q,'romain grading'!$A:$A,$A3,'romain grading'!$B:$B,$B3),SUMIFS('nishita grading'!Q:Q,'nishita grading'!$A:$A,$A3,'nishita grading'!$B:$B,$B3))) | R3: =44-SUM(D3:Q3)
A4: cooperative | B4: 123 | C4: nishita | D4: =IF($C4="faizan",SUMIFS('faizan grading'!D:D,'faizan grading'!$A:$A,$A4,'faizan grading'!$B:$B,$B4),IF($C4="romain",SUMIFS('romain grading'!D:D,'romain grading'!$A:$A,$A4,'romain grading'!$B:$B,$B4),SUMIFS('nishita grading'!D:D,'nishita grading'!$A:$A,$A4,'nishita grading'!$B:$B,$B4))) | E4: =IF($C4="faizan",SUMIFS('faizan grading'!E:E,'faizan grading'!$A:$A,$A4,'faizan grading'!$B:$B,$B4),IF($C4="romain",SUMIFS('romain grading'!E:E,'romain grading'!$A:$A,$A4,'romain grading'!$B:$B,$B4),SUMIFS('nishita grading'!E:E,'nishita grading'!$A:$A,$A4,'nishita grading'!$B:$B,$B4))) | F4: =IF($C4="faizan",SUMIFS('faizan grading'!F:F,'faizan grading'!$A:$A,$A4,'faizan grading'!$B:$B,$B4),IF($C4="romain",SUMIFS('romain grading'!F:F,'romain grading'!$A:$A,$A4,'romain grading'!$B:$B,$B4),SUMIFS('nishita grading'!F:F,'nishita grading'!$A:$A,$A4,'nishita grading'!$B:$B,$B4))) | G4: =IF($C4="faizan",SUMIFS('faizan grading'!G:G,'faizan grading'!$A:$A,$A4,'faizan grading'!$B:$B,$B4),IF($C4="romain",SUMIFS('romain grading'!G:G,'romain grading'!$A:$A,$A4,'romain grading'!$B:$B,$B4),SUMIFS('nishita grading'!G:G,'nishita grading'!$A:$A,$A4,'nishita grading'!$B:$B,$B4))) | H4: =IF($C4="faizan",SUMIFS('faizan grading'!H:H,'faizan grading'!$A:$A,$A4,'faizan grading'!$B:$B,$B4),IF($C4="romain",SUMIFS('romain grading'!H:H,'romain grading'!$A:$A,$A4,'romain grading'!$B:$B,$B4),SUMIFS('nishita grading'!H:H,'nishita grading'!$A:$A,$A4,'nishita grading'!$B:$B,$B4))) | I4: =IF($C4="faizan",SUMIFS('faizan grading'!I:I,'faizan grading'!$A:$A,$A4,'faizan grading'!$B:$B,$B4),IF($C4="romain",SUMIFS('romain grading'!I:I,'romain grading'!$A:$A,$A4,'romain grading'!$B:$B,$B4),SUMIFS('nishita grading'!I:I,'nishita grading'!$A:$A,$A4,'nishita grading'!$B:$B,$B4))) | J4: =IF($C4="faizan",SUMIFS('faizan grading'!J:J,'faizan grading'!$A:$A,$A4,'faizan grading'!$B:$B,$B4),IF($C4="romain",SUMIFS('romain grading'!J:J,'romain grading'!$A:$A,$A4,'romain grading'!$B:$B,$B4),SUMIFS('nishita grading'!J:J,'nishita grading'!$A:$A,$A4,'nishita grading'!$B:$B,$B4))) | K4: =IF($C4="faizan",SUMIFS('faizan grading'!K:K,'faizan grading'!$A:$A,$A4,'faizan grading'!$B:$B,$B4),IF($C4="romain",SUMIFS('romain grading'!K:K,'romain grading'!$A:$A,$A4,'romain grading'!$B:$B,$B4),SUMIFS('nishita grading'!K:K,'nishita grading'!$A:$A,$A4,'nishita grading'!$B:$B,$B4))) | L4: =IF($C4="faizan",SUMIFS('faizan grading'!L:L,'faizan grading'!$A:$A,$A4,'faizan grading'!$B:$B,$B4),IF($C4="romain",SUMIFS('romain grading'!L:L,'romain grading'!$A:$A,$A4,'romain grading'!$B:$B,$B4),SUMIFS('nishita grading'!L:L,'nishita grading'!$A:$A,$A4,'nishita grading'!$B:$B,$B4))) | M4: =IF($C4="faizan",SUMIFS('faizan grading'!M:M,'faizan grading'!$A:$A,$A4,'faizan grading'!$B:$B,$B4),IF($C4="romain",SUMIFS('romain grading'!M:M,'romain grading'!$A:$A,$A4,'romain grading'!$B:$B,$B4),SUMIFS('nishita grading'!M:M,'nishita grading'!$A:$A,$A4,'nishita grading'!$B:$B,$B4))) | N4: =IF($C4="faizan",SUMIFS('faizan grading'!N:N,'faizan grading'!$A:$A,$A4,'faizan grading'!$B:$B,$B4),IF($C4="romain",SUMIFS('romain grading'!N:N,'romain grading'!$A:$A,$A4,'romain grading'!$B:$B,$B4),SUMIFS('nishita grading'!N:N,'nishita grading'!$A:$A,$A4,'nishita grading'!$B:$B,$B4))) | O4: =IF($C4="faizan",SUMIFS('faizan grading'!O:O,'faizan grading'!$A:$A,$A4,'faizan grading'!$B:$B,$B4),IF($C4="romain",SUMIFS('romain grading'!O:O,'romain grading'!$A:$A,$A4,'romain grading'!$B:$B,$B4),SUMIFS('nishita grading'!O:O,'nishita grading'!$A:$A,$A4,'nishita grading'!$B:$B,$B4))) | P4: =IF($C4="faizan",SUMIFS('faizan grading'!P:P,'faizan grading'!$A:$A,$A4,'faizan grading'!$B:$B,$B4),IF($C4="romain",SUMIFS('romain grading'!P:P,'romain grading'!$A:$A,$A4,'romain grading'!$B:$B,$B4),SUMIFS('nishita grading'!P:P,'nishita grading'!$A:$A,$A4,'nishita grading'!$B:$B,$B4))) | Q4: =IF($C4="faizan",SUMIFS('faizan grading'!Q:Q,'faizan grading'!$A:$A,$A4,'faizan grading'!$B:$B,$B4),IF($C4="romain",SUMIFS('romain grading'!Q:Q,'romain grading'!$A:$A,$A4,'romain grading'!$B:$B,$B4),SUMIFS('nishita grading'!Q:Q,'nishita grading'!$A:$A,$A4,'nishita grading'!$B:$B,$B4))) | R4: =44-SUM(D4:Q4)
A5: clueless | B5: 52 | C5: faizan | D5: =IF($C5="faizan",SUMIFS('faizan grading'!D:D,'faizan grading'!$A:$A,$A5,'faizan grading'!$B:$B,$B5),IF($C5="romain",SUMIFS('romain grading'!D:D,'romain grading'!$A:$A,$A5,'romain grading'!$B:$B,$B5),SUMIFS('nishita grading'!D:D,'nishita grading'!$A:$A,$A5,'nishita grading'!$B:$B,$B5))) | E5: =IF($C5="faizan",SUMIFS('faizan grading'!E:E,'faizan grading'!$A:$A,$A5,'faizan grading'!$B:$B,$B5),IF($C5="romain",SUMIFS('romain grading'!E:E,'romain grading'!$A:$A,$A5,'romain grading'!$B:$B,$B5),SUMIFS('nishita grading'!E:E,'nishita grading'!$A:$A,$A5,'nishita grading'!$B:$B,$B5))) | F5: =IF($C5="faizan",SUMIFS('faizan grading'!F:F,'faizan grading'!$A:$A,$A5,'faizan grading'!$B:$B,$B5),IF($C5="romain",SUMIFS('romain grading'!F:F,'romain grading'!$A:$A,$A5,'romain grading'!$B:$B,$B5),SUMIFS('nishita grading'!F:F,'nishita grading'!$A:$A,$A5,'nishita grading'!$B:$B,$B5))) | G5: =IF($C5="faizan",SUMIFS('faizan grading'!G:G,'faizan grading'!$A:$A,$A5,'faizan grading'!$B:$B,$B5),IF($C5="romain",SUMIFS('romain grading'!G:G,'romain grading'!$A:$A,$A5,'romain grading'!$B:$B,$B5),SUMIFS('nishita grading'!G:G,'nishita grading'!$A:$A,$A5,'nishita grading'!$B:$B,$B5))) | H5: =IF($C5="faizan",SUMIFS('faizan grading'!H:H,'faizan grading'!$A:$A,$A5,'faizan grading'!$B:$B,$B5),IF($C5="romain",SUMIFS('romain grading'!H:H,'romain grading'!$A:$A,$A5,'romain grading'!$B:$B,$B5),SUMIFS('nishita grading'!H:H,'nishita grading'!$A:$A,$A5,'nishita grading'!$B:$B,$B5))) | I5: =IF($C5="faizan",SUMIFS('faizan grading'!I:I,'faizan grading'!$A:$A,$A5,'faizan grading'!$B:$B,$B5),IF($C5="romain",SUMIFS('romain grading'!I:I,'romain grading'!$A:$A,$A5,'romain grading'!$B:$B,$B5),SUMIFS('nishita grading'!I:I,'nishita grading'!$A:$A,$A5,'nishita grading'!$B:$B,$B5))) | J5: =IF($C5="faizan",SUMIFS('faizan grading'!J:J,'faizan grading'!$A:$A,$A5,'faizan grading'!$B:$B,$B5),IF($C5="romain",SUMIFS('romain grading'!J:J,'romain grading'!$A:$A,$A5,'romain grading'!$B:$B,$B5),SUMIFS('nishita grading'!J:J,'nishita grading'!$A:$A,$A5,'nishita grading'!$B:$B,$B5))) | K5: =IF($C5="faizan",SUMIFS('faizan grading'!K:K,'faizan grading'!$A:$A,$A5,'faizan grading'!$B:$B,$B5),IF($C5="romain",SUMIFS('romain grading'!K:K,'romain grading'!$A:$A,$A5,'romain grading'!$B:$B,$B5),SUMIFS('nishita grading'!K:K,'nishita grading'!$A:$A,$A5,'nishita grading'!$B:$B,$B5))) | L5: =IF($C5="faizan",SUMIFS('faizan grading'!L:L,'faizan grading'!$A:$A,$A5,'faizan grading'!$B:$B,$B5),IF($C5="romain",SUMIFS('romain grading'!L:L,'romain grading'!$A:$A,$A5,'romain grading'!$B:$B,$B5),SUMIFS('nishita grading'!L:L,'nishita grading'!$A:$A,$A5,'nishita grading'!$B:$B,$B5))) | M5: =IF($C5="faizan",SUMIFS('faizan grading'!M:M,'faizan grading'!$A:$A,$A5,'faizan grading'!$B:$B,$B5),IF($C5="romain",SUMIFS('romain grading'!M:M,'romain grading'!$A:$A,$A5,'romain grading'!$B:$B,$B5),SUMIFS('nishita grading'!M:M,'nishita grading'!$A:$A,$A5,'nishita grading'!$B:$B,$B5))) | N5: =IF($C5="faizan",SUMIFS('faizan grading'!N:N,'faizan grading'!$A:$A,$A5,'faizan grading'!$B:$B,$B5),IF($C5="romain",SUMIFS('romain grading'!N:N,'romain grading'!$A:$A,$A5,'romain grading'!$B:$B,$B5),SUMIFS('nishita grading'!N:N,'nishita grading'!$A:$A,$A5,'nishita grading'!$B:$B,$B5))) | O5: =IF($C5="faizan",SUMIFS('faizan grading'!O:O,'faizan grading'!$A:$A,$A5,'faizan grading'!$B:$B,$B5),IF($C5="romain",SUMIFS('romain grading'!O:O,'romain grading'!$A:$A,$A5,'romain grading'!$B:$B,$B5),SUMIFS('nishita grading'!O:O,'nishita grading'!$A:$A,$A5,'nishita grading'!$B:$B,$B5))) | P5: =IF($C5="faizan",SUMIFS('faizan grading'!P:P,'faizan grading'!$A:$A,$A5,'faizan grading'!$B:$B,$B5),IF($C5="romain",SUMIFS('romain grading'!P:P,'romain grading'!$A:$A,$A5,'romain grading'!$B:$B,$B5),SUMIFS('nishita grading'!P:P,'nishita grading'!$A:$A,$A5,'nishita grading'!$B:$B,$B5))) | Q5: =IF($C5="faizan",SUMIFS('faizan grading'!Q:Q,'faizan grading'!$A:$A,$A5,'faizan grading'!$B:$B,$B5),IF($C5="romain",SUMIFS('romain grading'!Q:Q,'romain grading'!$A:$A,$A5,'romain grading'!$B:$B,$B5),SUMIFS('nishita grading'!Q:Q,'nishita grading'!$A:$A,$A5,'nishita grading'!$B:$B,$B5))) | R5: =44-SUM(D5:Q5)
A6: clueless | B6: 52 | C6: romain | D6: =IF($C6="faizan",SUMIFS('faizan grading'!D:D,'faizan grading'!$A:$A,$A6,'faizan grading'!$B:$B,$B6),IF($C6="romain",SUMIFS('romain grading'!D:D,'romain grading'!$A:$A,$A6,'romain grading'!$B:$B,$B6),SUMIFS('nishita grading'!D:D,'nishita grading'!$A:$A,$A6,'nishita grading'!$B:$B,$B6))) | E6: =IF($C6="faizan",SUMIFS('faizan grading'!E:E,'faizan grading'!$A:$A,$A6,'faizan grading'!$B:$B,$B6),IF($C6="romain",SUMIFS('romain grading'!E:E,'romain grading'!$A:$A,$A6,'romain grading'!$B:$B,$B6),SUMIFS('nishita grading'!E:E,'nishita grading'!$A:$A,$A6,'nishita grading'!$B:$B,$B6))) | F6: =IF($C6="faizan",SUMIFS('faizan grading'!F:F,'faizan grading'!$A:$A,$A6,'faizan grading'!$B:$B,$B6),IF($C6="romain",SUMIFS('romain grading'!F:F,'romain grading'!$A:$A,$A6,'romain grading'!$B:$B,$B6),SUMIFS('nishita grading'!F:F,'nishita grading'!$A:$A,$A6,'nishita grading'!$B:$B,$B6))) | G6: =IF($C6="faizan",SUMIFS('faizan grading'!G:G,'faizan grading'!$A:$A,$A6,'faizan grading'!$B:$B,$B6),IF($C6="romain",SUMIFS('romain grading'!G:G,'romain grading'!$A:$A,$A6,'romain grading'!$B:$B,$B6),SUMIFS('nishita grading'!G:G,'nishita grading'!$A:$A,$A6,'nishita grading'!$B:$B,$B6))) | H6: =IF($C6="faizan",SUMIFS('faizan grading'!H:H,'faizan grading'!$A:$A,$A6,'faizan grading'!$B:$B,$B6),IF($C6="romain",SUMIFS('romain grading'!H:H,'romain grading'!$A:$A,$A6,'romain grading'!$B:$B,$B6),SUMIFS('nishita grading'!H:H,'nishita grading'!$A:$A,$A6,'nishita grading'!$B:$B,$B6))) | I6: =IF($C6="faizan",SUMIFS('faizan grading'!I:I,'faizan grading'!$A:$A,$A6,'faizan grading'!$B:$B,$B6),IF($C6="romain",SUMIFS('romain grading'!I:I,'romain grading'!$A:$A,$A6,'romain grading'!$B:$B,$B6),SUMIFS('nishita grading'!I:I,'nishita grading'!$A:$A,$A6,'nishita grading'!$B:$B,$B6))) | J6: =IF($C6="faizan",SUMIFS('faizan grading'!J:J,'faizan grading'!$A:$A,$A6,'faizan grading'!$B:$B,$B6),IF($C6="romain",SUMIFS('romain grading'!J:J,'romain grading'!$A:$A,$A6,'romain grading'!$B:$B,$B6),SUMIFS('nishita grading'!J:J,'nishita grading'!$A:$A,$A6,'nishita grading'!$B:$B,$B6))) | K6: =IF($C6="faizan",SUMIFS('faizan grading'!K:K,'faizan grading'!$A:$A,$A6,'faizan grading'!$B:$B,$B6),IF($C6="romain",SUMIFS('romain grading'!K:K,'romain grading'!$A:$A,$A6,'romain grading'!$B:$B,$B6),SUMIFS('nishita grading'!K:K,'nishita grading'!$A:$A,$A6,'nishita grading'!$B:$B,$B6))) | L6: =IF($C6="faizan",SUMIFS('faizan grading'!L:L,'faizan grading'!$A:$A,$A6,'faizan grading'!$B:$B,$B6),IF($C6="romain",SUMIFS('romain grading'!L:L,'romain grading'!$A:$A,$A6,'romain grading'!$B:$B,$B6),SUMIFS('nishita grading'!L:L,'nishita grading'!$A:$A,$A6,'nishita grading'!$B:$B,$B6))) | M6: =IF($C6="faizan",SUMIFS('faizan grading'!M:M,'faizan grading'!$A:$A,$A6,'faizan grading'!$B:$B,$B6),IF($C6="romain",SUMIFS('romain grading'!M:M,'romain grading'!$A:$A,$A6,'romain grading'!$B:$B,$B6),SUMIFS('nishita grading'!M:M,'nishita grading'!$A:$A,$A6,'nishita grading'!$B:$B,$B6))) | N6: =IF($C6="faizan",SUMIFS('faizan grading'!N:N,'faizan grading'!$A:$A,$A6,'faizan grading'!$B:$B,$B6),IF($C6="romain",SUMIFS('romain grading'!N:N,'romain grading'!$A:$A,$A6,'romain grading'!$B:$B,$B6),SUMIFS('nishita grading'!N:N,'nishita grading'!$A:$A,$A6,'nishita grading'!$B:$B,$B6))) | O6: =IF($C6="faizan",SUMIFS('faizan grading'!O:O,'faizan grading'!$A:$A,$A6,'faizan grading'!$B:$B,$B6),IF($C6="romain",SUMIFS('romain grading'!O:O,'romain grading'!$A:$A,$A6,'romain grading'!$B:$B,$B6),SUMIFS('nishita grading'!O:O,'nishita grading'!$A:$A,$A6,'nishita grading'!$B:$B,$B6))) | P6: =IF($C6="faizan",SUMIFS('faizan grading'!P:P,'faizan grading'!$A:$A,$A6,'faizan grading'!$B:$B,$B6),IF($C6="romain",SUMIFS('romain grading'!P:P,'romain grading'!$A:$A,$A6,'romain grading'!$B:$B,$B6),SUMIFS('nishita grading'!P:P,'nishita grading'!$A:$A,$A6,'nishita grading'!$B:$B,$B6))) | Q6: =IF($C6="faizan",SUMIFS('faizan grading'!Q:Q,'faizan grading'!$A:$A,$A6,'faizan grading'!$B:$B,$B6),IF($C6="romain",SUMIFS('romain grading'!Q:Q,'romain grading'!$A:$A,$A6,'romain grading'!$B:$B,$B6),SUMIFS('nishita grading'!Q:Q,'nishita grading'!$A:$A,$A6,'nishita grading'!$B:$B,$B6))) | R6: =44-SUM(D6:Q6)
A7: clueless | B7: 52 | C7: nishita | D7: =IF($C7="faizan",SUMIFS('faizan grading'!D:D,'faizan grading'!$A:$A,$A7,'faizan grading'!$B:$B,$B7),IF($C7="romain",SUMIFS('romain grading'!D:D,'romain grading'!$A:$A,$A7,'romain grading'!$B:$B,$B7),SUMIFS('nishita grading'!D:D,'nishita grading'!$A:$A,$A7,'nishita grading'!$B:$B,$B7))) | E7: =IF($C7="faizan",SUMIFS('faizan grading'!E:E,'faizan grading'!$A:$A,$A7,'faizan grading'!$B:$B,$B7),IF($C7="romain",SUMIFS('romain grading'!E:E,'romain grading'!$A:$A,$A7,'romain grading'!$B:$B,$B7),SUMIFS('nishita grading'!E:E,'nishita grading'!$A:$A,$A7,'nishita grading'!$B:$B,$B7))) | F7: =IF($C7="faizan",SUMIFS('faizan grading'!F:F,'faizan grading'!$A:$A,$A7,'faizan grading'!$B:$B,$B7),IF($C7="romain",SUMIFS('romain grading'!F:F,'romain grading'!$A:$A,$A7,'romain grading'!$B:$B,$B7),SUMIFS('nishita grading'!F:F,'nishita grading'!$A:$A,$A7,'nishita grading'!$B:$B,$B7))) | G7: =IF($C7="faizan",SUMIFS('faizan grading'!G:G,'faizan grading'!$A:$A,$A7,'faizan grading'!$B:$B,$B7),IF($C7="romain",SUMIFS('romain grading'!G:G,'romain grading'!$A:$A,$A7,'romain grading'!$B:$B,$B7),SUMIFS('nishita grading'!G:G,'nishita grading'!$A:$A,$A7,'nishita grading'!$B:$B,$B7))) | H7: =IF($C7="faizan",SUMIFS('faizan grading'!H:H,'faizan grading'!$A:$A,$A7,'faizan grading'!$B:$B,$B7),IF($C7="romain",SUMIFS('romain grading'!H:H,'romain grading'!$A:$A,$A7,'romain grading'!$B:$B,$B7),SUMIFS('nishita grading'!H:H,'nishita grading'!$A:$A,$A7,'nishita grading'!$B:$B,$B7))) | I7: =IF($C7="faizan",SUMIFS('faizan grading'!I:I,'faizan grading'!$A:$A,$A7,'faizan grading'!$B:$B,$B7),IF($C7="romain",SUMIFS('romain grading'!I:I,'romain grading'!$A:$A,$A7,'romain grading'!$B:$B,$B7),SUMIFS('nishita grading'!I:I,'nishita grading'!$A:$A,$A7,'nishita grading'!$B:$B,$B7))) | J7: =IF($C7="faizan",SUMIFS('faizan grading'!J:J,'faizan grading'!$A:$A,$A7,'faizan grading'!$B:$B,$B7),IF($C7="romain",SUMIFS('romain grading'!J:J,'romain grading'!$A:$A,$A7,'romain grading'!$B:$B,$B7),SUMIFS('nishita grading'!J:J,'nishita grading'!$A:$A,$A7,'nishita grading'!$B:$B,$B7))) | K7: =IF($C7="faizan",SUMIFS('faizan grading'!K:K,'faizan grading'!$A:$A,$A7,'faizan grading'!$B:$B,$B7),IF($C7="romain",SUMIFS('romain grading'!K:K,'romain grading'!$A:$A,$A7,'romain grading'!$B:$B,$B7),SUMIFS('nishita grading'!K:K,'nishita grading'!$A:$A,$A7,'nishita grading'!$B:$B,$B7))) | L7: =IF($C7="faizan",SUMIFS('faizan grading'!L:L,'faizan grading'!$A:$A,$A7,'faizan grading'!$B:$B,$B7),IF($C7="romain",SUMIFS('romain grading'!L:L,'romain grading'!$A:$A,$A7,'romain grading'!$B:$B,$B7),SUMIFS('nishita grading'!L:L,'nishita grading'!$A:$A,$A7,'nishita grading'!$B:$B,$B7))) | M7: =IF($C7="faizan",SUMIFS('faizan grading'!M:M,'faizan grading'!$A:$A,$A7,'faizan grading'!$B:$B,$B7),IF($C7="romain",SUMIFS('romain grading'!M:M,'romain grading'!$A:$A,$A7,'romain grading'!$B:$B,$B7),SUMIFS('nishita grading'!M:M,'nishita grading'!$A:$A,$A7,'nishita grading'!$B:$B,$B7))) | N7: =IF($C7="faizan",SUMIFS('faizan grading'!N:N,'faizan grading'!$A:$A,$A7,'faizan grading'!$B:$B,$B7),IF($C7="romain",SUMIFS('romain grading'!N:N,'romain grading'!$A:$A,$A7,'romain grading'!$B:$B,$B7),SUMIFS('nishita grading'!N:N,'nishita grading'!$A:$A,$A7,'nishita grading'!$B:$B,$B7))) | O7: =IF($C7="faizan",SUMIFS('faizan grading'!O:O,'faizan grading'!$A:$A,$A7,'faizan grading'!$B:$B,$B7),IF($C7="romain",SUMIFS('romain grading'!O:O,'romain grading'!$A:$A,$A7,'romain grading'!$B:$B,$B7),SUMIFS('nishita grading'!O:O,'nishita grading'!$A:$A,$A7,'nishita grading'!$B:$B,$B7))) | P7: =IF($C7="faizan",SUMIFS('faizan grading'!P:P,'faizan grading'!$A:$A,$A7,'faizan grading'!$B:$B,$B7),IF($C7="romain",SUMIFS('romain grading'!P:P,'romain grading'!$A:$A,$A7,'romain grading'!$B:$B,$B7),SUMIFS('nishita grading'!P:P,'nishita grading'!$A:$A,$A7,'nishita grading'!$B:$B,$B7))) | Q7: =IF($C7="faizan",SUMIFS('faizan grading'!Q:Q,'faizan grading'!$A:$A,$A7,'faizan grading'!$B:$B,$B7),IF($C7="romain",SUMIFS('romain grading'!Q:Q,'romain grading'!$A:$A,$A7,'romain grading'!$B:$B,$B7),SUMIFS('nishita grading'!Q:Q,'nishita grading'!$A:$A,$A7,'nishita grading'!$B:$B,$B7))) | R7: =44-SUM(D7:Q7)
A8: cooperative | B8: 110 | C8: faizan | D8: =IF($C8="faizan",SUMIFS('faizan grading'!D:D,'faizan grading'!$A:$A,$A8,'faizan grading'!$B:$B,$B8),IF($C8="romain",SUMIFS('romain grading'!D:D,'romain grading'!$A:$A,$A8,'romain grading'!$B:$B,$B8),SUMIFS('nishita grading'!D:D,'nishita grading'!$A:$A,$A8,'nishita grading'!$B:$B,$B8))) | E8: =IF($C8="faizan",SUMIFS('faizan grading'!E:E,'faizan grading'!$A:$A,$A8,'faizan grading'!$B:$B,$B8),IF($C8="romain",SUMIFS('romain grading'!E:E,'romain grading'!$A:$A,$A8,'romain grading'!$B:$B,$B8),SUMIFS('nishita grading'!E:E,'nishita grading'!$A:$A,$A8,'nishita grading'!$B:$B,$B8))) | F8: =IF($C8="faizan",SUMIFS('faizan grading'!F:F,'faizan grading'!$A:$A,$A8,'faizan grading'!$B:$B,$B8),IF($C8="romain",SUMIFS('romain grading'!F:F,'romain grading'!$A:$A,$A8,'romain grading'!$B:$B,$B8),SUMIFS('nishita grading'!F:F,'nishita grading'!$A:$A,$A8,'nishita grading'!$B:$B,$B8))) | G8: =IF($C8="faizan",SUMIFS('faizan grading'!G:G,'faizan grading'!$A:$A,$A8,'faizan grading'!$B:$B,$B8),IF($C8="romain",SUMIFS('romain grading'!G:G,'romain grading'!$A:$A,$A8,'romain grading'!$B:$B,$B8),SUMIFS('nishita grading'!G:G,'nishita grading'!$A:$A,$A8,'nishita grading'!$B:$B,$B8))) | H8: =IF($C8="faizan",SUMIFS('faizan grading'!H:H,'faizan grading'!$A:$A,$A8,'faizan grading'!$B:$B,$B8),IF($C8="romain",SUMIFS('romain grading'!H:H,'romain grading'!$A:$A,$A8,'romain grading'!$B:$B,$B8),SUMIFS('nishita grading'!H:H,'nishita grading'!$A:$A,$A8,'nishita grading'!$B:$B,$B8))) | I8: =IF($C8="faizan",SUMIFS('faizan grading'!I:I,'faizan grading'!$A:$A,$A8,'faizan grading'!$B:$B,$B8),IF($C8="romain",SUMIFS('romain grading'!I:I,'romain grading'!$A:$A,$A8,'romain grading'!$B:$B,$B8),SUMIFS('nishita grading'!I:I,'nishita grading'!$A:$A,$A8,'nishita grading'!$B:$B,$B8))) | J8: =IF($C8="faizan",SUMIFS('faizan grading'!J:J,'faizan grading'!$A:$A,$A8,'faizan grading'!$B:$B,$B8),IF($C8="romain",SUMIFS('romain grading'!J:J,'romain grading'!$A:$A,$A8,'romain grading'!$B:$B,$B8),SUMIFS('nishita grading'!J:J,'nishita grading'!$A:$A,$A8,'nishita grading'!$B:$B,$B8))) | K8: =IF($C8="faizan",SUMIFS('faizan grading'!K:K,'faizan grading'!$A:$A,$A8,'faizan grading'!$B:$B,$B8),IF($C8="romain",SUMIFS('romain grading'!K:K,'romain grading'!$A:$A,$A8,'romain grading'!$B:$B,$B8),SUMIFS('nishita grading'!K:K,'nishita grading'!$A:$A,$A8,'nishita grading'!$B:$B,$B8))) | L8: =IF($C8="faizan",SUMIFS('faizan grading'!L:L,'faizan grading'!$A:$A,$A8,'faizan grading'!$B:$B,$B8),IF($C8="romain",SUMIFS('romain grading'!L:L,'romain grading'!$A:$A,$A8,'romain grading'!$B:$B,$B8),SUMIFS('nishita grading'!L:L,'nishita grading'!$A:$A,$A8,'nishita grading'!$B:$B,$B8))) | M8: =IF($C8="faizan",SUMIFS('faizan grading'!M:M,'faizan grading'!$A:$A,$A8,'faizan grading'!$B:$B,$B8),IF($C8="romain",SUMIFS('romain grading'!M:M,'romain grading'!$A:$A,$A8,'romain grading'!$B:$B,$B8),SUMIFS('nishita grading'!M:M,'nishita grading'!$A:$A,$A8,'nishita grading'!$B:$B,$B8))) | N8: =IF($C8="faizan",SUMIFS('faizan grading'!N:N,'faizan grading'!$A:$A,$A8,'faizan grading'!$B:$B,$B8),IF($C8="romain",SUMIFS('romain grading'!N:N,'romain grading'!$A:$A,$A8,'romain grading'!$B:$B,$B8),SUMIFS('nishita grading'!N:N,'nishita grading'!$A:$A,$A8,'nishita grading'!$B:$B,$B8))) | O8: =IF($C8="faizan",SUMIFS('faizan grading'!O:O,'faizan grading'!$A:$A,$A8,'faizan grading'!$B:$B,$B8),IF($C8="romain",SUMIFS('romain grading'!O:O,'romain grading'!$A:$A,$A8,'romain grading'!$B:$B,$B8),SUMIFS('nishita grading'!O:O,'nishita grading'!$A:$A,$A8,'nishita grading'!$B:$B,$B8))) | P8: =IF($C8="faizan",SUMIFS('faizan grading'!P:P,'faizan grading'!$A:$A,$A8,'faizan grading'!$B:$B,$B8),IF($C8="romain",SUMIFS('romain grading'!P:P,'romain grading'!$A:$A,$A8,'romain grading'!$B:$B,$B8),SUMIFS('nishita grading'!P:P,'nishita grading'!$A:$A,$A8,'nishita grading'!$B:$B,$B8))) | Q8: =IF($C8="faizan",SUMIFS('faizan grading'!Q:Q,'faizan grading'!$A:$A,$A8,'faizan grading'!$B:$B,$B8),IF($C8="romain",SUMIFS('romain grading'!Q:Q,'romain grading'!$A:$A,$A8,'romain grading'!$B:$B,$B8),SUMIFS('nishita grading'!Q:Q,'nishita grading'!$A:$A,$A8,'nishita grading'!$B:$B,$B8))) | R8: =44-SUM(D8:Q8)
A9: cooperative | B9: 110 | C9: romain | D9: =IF($C9="faizan",SUMIFS('faizan grading'!D:D,'faizan grading'!$A:$A,$A9,'faizan grading'!$B:$B,$B9),IF($C9="romain",SUMIFS('romain grading'!D:D,'romain grading'!$A:$A,$A9,'romain grading'!$B:$B,$B9),SUMIFS('nishita grading'!D:D,'nishita grading'!$A:$A,$A9,'nishita grading'!$B:$B,$B9))) | E9: =IF($C9="faizan",SUMIFS('faizan grading'!E:E,'faizan grading'!$A:$A,$A9,'faizan grading'!$B:$B,$B9),IF($C9="romain",SUMIFS('romain grading'!E:E,'romain grading'!$A:$A,$A9,'romain grading'!$B:$B,$B9),SUMIFS('nishita grading'!E:E,'nishita grading'!$A:$A,$A9,'nishita grading'!$B:$B,$B9))) | F9: =IF($C9="faizan",SUMIFS('faizan grading'!F:F,'faizan grading'!$A:$A,$A9,'faizan grading'!$B:$B,$B9),IF($C9="romain",SUMIFS('romain grading'!F:F,'romain grading'!$A:$A,$A9,'romain grading'!$B:$B,$B9),SUMIFS('nishita grading'!F:F,'nishita grading'!$A:$A,$A9,'nishita grading'!$B:$B,$B9))) | G9: =IF($C9="faizan",SUMIFS('faizan grading'!G:G,'faizan grading'!$A:$A,$A9,'faizan grading'!$B:$B,$B9),IF($C9="romain",SUMIFS('romain grading'!G:G,'romain grading'!$A:$A,$A9,'romain grading'!$B:$B,$B9),SUMIFS('nishita grading'!G:G,'nishita grading'!$A:$A,$A9,'nishita grading'!$B:$B,$B9))) | H9: =IF($C9="faizan",SUMIFS('faizan grading'!H:H,'faizan grading'!$A:$A,$A9,'faizan grading'!$B:$B,$B9),IF($C9="romain",SUMIFS('romain grading'!H:H,'romain grading'!$A:$A,$A9,'romain grading'!$B:$B,$B9),SUMIFS('nishita grading'!H:H,'nishita grading'!$A:$A,$A9,'nishita grading'!$B:$B,$B9))) | I9: =IF($C9="faizan",SUMIFS('faizan grading'!I:I,'faizan grading'!$A:$A,$A9,'faizan grading'!$B:$B,$B9),IF($C9="romain",SUMIFS('romain grading'!I:I,'romain grading'!$A:$A,$A9,'romain grading'!$B:$B,$B9),SUMIFS('nishita grading'!I:I,'nishita grading'!$A:$A,$A9,'nishita grading'!$B:$B,$B9))) | J9: =IF($C9="faizan",SUMIFS('faizan grading'!J:J,'faizan grading'!$A:$A,$A9,'faizan grading'!$B:$B,$B9),IF($C9="romain",SUMIFS('romain grading'!J:J,'romain grading'!$A:$A,$A9,'romain grading'!$B:$B,$B9),SUMIFS('nishita grading'!J:J,'nishita grading'!$A:$A,$A9,'nishita grading'!$B:$B,$B9))) | K9: =IF($C9="faizan",SUMIFS('faizan grading'!K:K,'faizan grading'!$A:$A,$A9,'faizan grading'!$B:$B,$B9),IF($C9="romain",SUMIFS('romain grading'!K:K,'romain grading'!$A:$A,$A9,'romain grading'!$B:$B,$B9),SUMIFS('nishita grading'!K:K,'nishita grading'!$A:$A,$A9,'nishita grading'!$B:$B,$B9))) | L9: =IF($C9="faizan",SUMIFS('faizan grading'!L:L,'faizan grading'!$A:$A,$A9,'faizan grading'!$B:$B,$B9),IF($C9="romain",SUMIFS('romain grading'!L:L,'romain grading'!$A:$A,$A9,'romain grading'!$B:$B,$B9),SUMIFS('nishita grading'!L:L,'nishita grading'!$A:$A,$A9,'nishita grading'!$B:$B,$B9))) | M9: =IF($C9="faizan",SUMIFS('faizan grading'!M:M,'faizan grading'!$A:$A,$A9,'faizan grading'!$B:$B,$B9),IF($C9="romain",SUMIFS('romain grading'!M:M,'romain grading'!$A:$A,$A9,'romain grading'!$B:$B,$B9),SUMIFS('nishita grading'!M:M,'nishita grading'!$A:$A,$A9,'nishita grading'!$B:$B,$B9))) | N9: =IF($C9="faizan",SUMIFS('faizan grading'!N:N,'faizan grading'!$A:$A,$A9,'faizan grading'!$B:$B,$B9),IF($C9="romain",SUMIFS('romain grading'!N:N,'romain grading'!$A:$A,$A9,'romain grading'!$B:$B,$B9),SUMIFS('nishita grading'!N:N,'nishita grading'!$A:$A,$A9,'nishita grading'!$B:$B,$B9))) | O9: =IF($C9="faizan",SUMIFS('faizan grading'!O:O,'faizan grading'!$A:$A,$A9,'faizan grading'!$B:$B,$B9),IF($C9="romain",SUMIFS('romain grading'!O:O,'romain grading'!$A:$A,$A9,'romain grading'!$B:$B,$B9),SUMIFS('nishita grading'!O:O,'nishita grading'!$A:$A,$A9,'nishita grading'!$B:$B,$B9))) | P9: =IF($C9="faizan",SUMIFS('faizan grading'!P:P,'faizan grading'!$A:$A,$A9,'faizan grading'!$B:$B,$B9),IF($C9="romain",SUMIFS('romain grading'!P:P,'romain grading'!$A:$A,$A9,'romain grading'!$B:$B,$B9),SUMIFS('nishita grading'!P:P,'nishita grading'!$A:$A,$A9,'nishita grading'!$B:$B,$B9))) | Q9: =IF($C9="faizan",SUMIFS('faizan grading'!Q:Q,'faizan grading'!$A:$A,$A9,'faizan grading'!$B:$B,$B9),IF($C9="romain",SUMIFS('romain grading'!Q:Q,'romain grading'!$A:$A,$A9,'romain grading'!$B:$B,$B9),SUMIFS('nishita grading'!Q:Q,'nishita grading'!$A:$A,$A9,'nishita grading'!$B:$B,$B9))) | R9: =44-SUM(D9:Q9)
A10: cooperative | B10: 110 | C10: nishita | D10: =IF($C10="faizan",SUMIFS('faizan grading'!D:D,'faizan grading'!$A:$A,$A10,'faizan grading'!$B:$B,$B10),IF($C10="romain",SUMIFS('romain grading'!D:D,'romain grading'!$A:$A,$A10,'romain grading'!$B:$B,$B10),SUMIFS('nishita grading'!D:D,'nishita grading'!$A:$A,$A10,'nishita grading'!$B:$B,$B10))) | E10: =IF($C10="faizan",SUMIFS('faizan grading'!E:E,'faizan grading'!$A:$A,$A10,'faizan grading'!$B:$B,$B10),IF($C10="romain",SUMIFS('romain grading'!E:E,'romain grading'!$A:$A,$A10,'romain grading'!$B:$B,$B10),SUMIFS('nishita grading'!E:E,'nishita grading'!$A:$A,$A10,'nishita grading'!$B:$B,$B10))) | F10: =IF($C10="faizan",SUMIFS('faizan grading'!F:F,'faizan grading'!$A:$A,$A10,'faizan grading'!$B:$B,$B10),IF($C10="romain",SUMIFS('romain grading'!F:F,'romain grading'!$A:$A,$A10,'romain grading'!$B:$B,$B10),SUMIFS('nishita grading'!F:F,'nishita grading'!$A:$A,$A10,'nishita grading'!$B:$B,$B10))) | G10: =IF($C10="faizan",SUMIFS('faizan grading'!G:G,'faizan grading'!$A:$A,$A10,'faizan grading'!$B:$B,$B10),IF($C10="romain",SUMIFS('romain grading'!G:G,'romain grading'!$A:$A,$A10,'romain grading'!$B:$B,$B10),SUMIFS('nishita grading'!G:G,'nishita grading'!$A:$A,$A10,'nishita grading'!$B:$B,$B10))) | H10: =IF($C10="faizan",SUMIFS('faizan grading'!H:H,'faizan grading'!$A:$A,$A10,'faizan grading'!$B:$B,$B10),IF($C10="romain",SUMIFS('romain grading'!H:H,'romain grading'!$A:$A,$A10,'romain grading'!$B:$B,$B10),SUMIFS('nishita grading'!H:H,'nishita grading'!$A:$A,$A10,'nishita grading'!$B:$B,$B10))) | I10: =IF($C10="faizan",SUMIFS('faizan grading'!I:I,'faizan grading'!$A:$A,$A10,'faizan grading'!$B:$B,$B10),IF($C10="romain",SUMIFS('romain grading'!I:I,'romain grading'!$A:$A,$A10,'romain grading'!$B:$B,$B10),SUMIFS('nishita grading'!I:I,'nishita grading'!$A:$A,$A10,'nishita grading'!$B:$B,$B10))) | J10: =IF($C10="faizan",SUMIFS('faizan grading'!J:J,'faizan grading'!$A:$A,$A10,'faizan grading'!$B:$B,$B10),IF($C10="romain",SUMIFS('romain grading'!J:J,'romain grading'!$A:$A,$A10,'romain grading'!$B:$B,$B10),SUMIFS('nishita grading'!J:J,'nishita grading'!$A:$A,$A10,'nishita grading'!$B:$B,$B10))) | K10: =IF($C10="faizan",SUMIFS('faizan grading'!K:K,'faizan grading'!$A:$A,$A10,'faizan grading'!$B:$B,$B10),IF($C10="romain",SUMIFS('romain grading'!K:K,'romain grading'!$A:$A,$A10,'romain grading'!$B:$B,$B10),SUMIFS('nishita grading'!K:K,'nishita grading'!$A:$A,$A10,'nishita grading'!$B:$B,$B10))) | L10: =IF($C10="faizan",SUMIFS('faizan grading'!L:L,'faizan grading'!$A:$A,$A10,'faizan grading'!$B:$B,$B10),IF($C10="romain",SUMIFS('romain grading'!L:L,'romain grading'!$A:$A,$A10,'romain grading'!$B:$B,$B10),SUMIFS('nishita grading'!L:L,'nishita grading'!$A:$A,$A10,'nishita grading'!$B:$B,$B10))) | M10: =IF($C10="faizan",SUMIFS('faizan grading'!M:M,'faizan grading'!$A:$A,$A10,'faizan grading'!$B:$B,$B10),IF($C10="romain",SUMIFS('romain grading'!M:M,'romain grading'!$A:$A,$A10,'romain grading'!$B:$B,$B10),SUMIFS('nishita grading'!M:M,'nishita grading'!$A:$A,$A10,'nishita grading'!$B:$B,$B10))) | N10: =IF($C10="faizan",SUMIFS('faizan grading'!N:N,'faizan grading'!$A:$A,$A10,'faizan grading'!$B:$B,$B10),IF($C10="romain",SUMIFS('romain grading'!N:N,'romain grading'!$A:$A,$A10,'romain grading'!$B:$B,$B10),SUMIFS('nishita grading'!N:N,'nishita grading'!$A:$A,$A10,'nishita grading'!$B:$B,$B10))) | O10: =IF($C10="faizan",SUMIFS('faizan grading'!O:O,'faizan grading'!$A:$A,$A10,'faizan grading'!$B:$B,$B10),IF($C10="romain",SUMIFS('romain grading'!O:O,'romain grading'!$A:$A,$A10,'romain grading'!$B:$B,$B10),SUMIFS('nishita grading'!O:O,'nishita grading'!$A:$A,$A10,'nishita grading'!$B:$B,$B10))) | P10: =IF($C10="faizan",SUMIFS('faizan grading'!P:P,'faizan grading'!$A:$A,$A10,'faizan grading'!$B:$B,$B10),IF($C10="romain",SUMIFS('romain grading'!P:P,'romain grading'!$A:$A,$A10,'romain grading'!$B:$B,$B10),SUMIFS('nishita grading'!P:P,'nishita grading'!$A:$A,$A10,'nishita grading'!$B:$B,$B10))) | Q10: =IF($C10="faizan",SUMIFS('faizan grading'!Q:Q,'faizan grading'!$A:$A,$A10,'faizan grading'!$B:$B,$B10),IF($C10="romain",SUMIFS('romain grading'!Q:Q,'romain grading'!$A:$A,$A10,'romain grading'!$B:$B,$B10),SUMIFS('nishita grading'!Q:Q,'nishita grading'!$A:$A,$A10,'nishita grading'!$B:$B,$B10))) | R10: =44-SUM(D10:Q10)
A11: cooperative | B11: 44 | C11: faizan | D11: =IF($C11="faizan",SUMIFS('faizan grading'!D:D,'faizan grading'!$A:$A,$A11,'faizan grading'!$B:$B,$B11),IF($C11="romain",SUMIFS('romain grading'!D:D,'romain grading'!$A:$A,$A11,'romain grading'!$B:$B,$B11),SUMIFS('nishita grading'!D:D,'nishita grading'!$A:$A,$A11,'nishita grading'!$B:$B,$B11))) | E11: =IF($C11="faizan",SUMIFS('faizan grading'!E:E,'faizan grading'!$A:$A,$A11,'faizan grading'!$B:$B,$B11),IF($C11="romain",SUMIFS('romain grading'!E:E,'romain grading'!$A:$A,$A11,'romain grading'!$B:$B,$B11),SUMIFS('nishita grading'!E:E,'nishita grading'!$A:$A,$A11,'nishita grading'!$B:$B,$B11))) | F11: =IF($C11="faizan",SUMIFS('faizan grading'!F:F,'faizan grading'!$A:$A,$A11,'faizan grading'!$B:$B,$B11),IF($C11="romain",SUMIFS('romain grading'!F:F,'romain grading'!$A:$A,$A11,'romain grading'!$B:$B,$B11),SUMIFS('nishita grading'!F:F,'nishita grading'!$A:$A,$A11,'nishita grading'!$B:$B,$B11))) | G11: =IF($C11="faizan",SUMIFS('faizan grading'!G:G,'faizan grading'!$A:$A,$A11,'faizan grading'!$B:$B,$B11),IF($C11="romain",SUMIFS('romain grading'!G:G,'romain grading'!$A:$A,$A11,'romain grading'!$B:$B,$B11),SUMIFS('nishita grading'!G:G,'nishita grading'!$A:$A,$A11,'nishita grading'!$B:$B,$B11))) | H11: =IF($C11="faizan",SUMIFS('faizan grading'!H:H,'faizan grading'!$A:$A,$A11,'faizan grading'!$B:$B,$B11),IF($C11="romain",SUMIFS('romain grading'!H:H,'romain grading'!$A:$A,$A11,'romain grading'!$B:$B,$B11),SUMIFS('nishita grading'!H:H,'nishita grading'!$A:$A,$A11,'nishita grading'!$B:$B,$B11))) | I11: =IF($C11="faizan",SUMIFS('faizan grading'!I:I,'faizan grading'!$A:$A,$A11,'faizan grading'!$B:$B,$B11),IF($C11="romain",SUMIFS('romain grading'!I:I,'romain grading'!$A:$A,$A11,'romain grading'!$B:$B,$B11),SUMIFS('nishita grading'!I:I,'nishita grading'!$A:$A,$A11,'nishita grading'!$B:$B,$B11))) | J11: =IF($C11="faizan",SUMIFS('faizan grading'!J:J,'faizan grading'!$A:$A,$A11,'faizan grading'!$B:$B,$B11),IF($C11="romain",SUMIFS('romain grading'!J:J,'romain grading'!$A:$A,$A11,'romain grading'!$B:$B,$B11),SUMIFS('nishita grading'!J:J,'nishita grading'!$A:$A,$A11,'nishita grading'!$B:$B,$B11))) | K11: =IF($C11="faizan",SUMIFS('faizan grading'!K:K,'faizan grading'!$A:$A,$A11,'faizan grading'!$B:$B,$B11),IF($C11="romain",SUMIFS('romain grading'!K:K,'romain grading'!$A:$A,$A11,'romain grading'!$B:$B,$B11),SUMIFS('nishita grading'!K:K,'nishita grading'!$A:$A,$A11,'nishita grading'!$B:$B,$B11))) | L11: =IF($C11="faizan",SUMIFS('faizan grading'!L:L,'faizan grading'!$A:$A,$A11,'faizan grading'!$B:$B,$B11),IF($C11="romain",SUMIFS('romain grading'!L:L,'romain grading'!$A:$A,$A11,'romain grading'!$B:$B,$B11),SUMIFS('nishita grading'!L:L,'nishita grading'!$A:$A,$A11,'nishita grading'!$B:$B,$B11))) | M11: =IF($C11="faizan",SUMIFS('faizan grading'!M:M,'faizan grading'!$A:$A,$A11,'faizan grading'!$B:$B,$B11),IF($C11="romain",SUMIFS('romain grading'!M:M,'romain grading'!$A:$A,$A11,'romain grading'!$B:$B,$B11),SUMIFS('nishita grading'!M:M,'nishita grading'!$A:$A,$A11,'nishita grading'!$B:$B,$B11))) | N11: =IF($C11="faizan",SUMIFS('faizan grading'!N:N,'faizan grading'!$A:$A,$A11,'faizan grading'!$B:$B,$B11),IF($C11="romain",SUMIFS('romain grading'!N:N,'romain grading'!$A:$A,$A11,'romain grading'!$B:$B,$B11),SUMIFS('nishita grading'!N:N,'nishita grading'!$A:$A,$A11,'nishita grading'!$B:$B,$B11))) | O11: =IF($C11="faizan",SUMIFS('faizan grading'!O:O,'faizan grading'!$A:$A,$A11,'faizan grading'!$B:$B,$B11),IF($C11="romain",SUMIFS('romain grading'!O:O,'romain grading'!$A:$A,$A11,'romain grading'!$B:$B,$B11),SUMIFS('nishita grading'!O:O,'nishita grading'!$A:$A,$A11,'nishita grading'!$B:$B,$B11))) | P11: =IF($C11="faizan",SUMIFS('faizan grading'!P:P,'faizan grading'!$A:$A,$A11,'faizan grading'!$B:$B,$B11),IF($C11="romain",SUMIFS('romain grading'!P:P,'romain grading'!$A:$A,$A11,'romain grading'!$B:$B,$B11),SUMIFS('nishita grading'!P:P,'nishita grading'!$A:$A,$A11,'nishita grading'!$B:$B,$B11))) | Q11: =IF($C11="faizan",SUMIFS('faizan grading'!Q:Q,'faizan grading'!$A:$A,$A11,'faizan grading'!$B:$B,$B11),IF($C11="romain",SUMIFS('romain grading'!Q:Q,'romain grading'!$A:$A,$A11,'romain grading'!$B:$B,$B11),SUMIFS('nishita grading'!Q:Q,'nishita grading'!$A:$A,$A11,'nishita grading'!$B:$B,$B11))) | R11: =44-SUM(D11:Q11)
A12: cooperative | B12: 44 | C12: romain | D12: =IF($C12="faizan",SUMIFS('faizan grading'!D:D,'faizan grading'!$A:$A,$A12,'faizan grading'!$B:$B,$B12),IF($C12="romain",SUMIFS('romain grading'!D:D,'romain grading'!$A:$A,$A12,'romain grading'!$B:$B,$B12),SUMIFS('nishita grading'!D:D,'nishita grading'!$A:$A,$A12,'nishita grading'!$B:$B,$B12))) | E12: =IF($C12="faizan",SUMIFS('faizan grading'!E:E,'faizan grading'!$A:$A,$A12,'faizan grading'!$B:$B,$B12),IF($C12="romain",SUMIFS('romain grading'!E:E,'romain grading'!$A:$A,$A12,'romain grading'!$B:$B,$B12),SUMIFS('nishita grading'!E:E,'nishita grading'!$A:$A,$A12,'nishita grading'!$B:$B,$B12))) | F12: =IF($C12="faizan",SUMIFS('faizan grading'!F:F,'faizan grading'!$A:$A,$A12,'faizan grading'!$B:$B,$B12),IF($C12="romain",SUMIFS('romain grading'!F:F,'romain grading'!$A:$A,$A12,'romain grading'!$B:$B,$B12),SUMIFS('nishita grading'!F:F,'nishita grading'!$A:$A,$A12,'nishita grading'!$B:$B,$B12))) | G12: =IF($C12="faizan",SUMIFS('faizan grading'!G:G,'faizan grading'!$A:$A,$A12,'faizan grading'!$B:$B,$B12),IF($C12="romain",SUMIFS('romain grading'!G:G,'romain grading'!$A:$A,$A12,'romain grading'!$B:$B,$B12),SUMIFS('nishita grading'!G:G,'nishita grading'!$A:$A,$A12,'nishita grading'!$B:$B,$B12))) | H12: =IF($C12="faizan",SUMIFS('faizan grading'!H:H,'faizan grading'!$A:$A,$A12,'faizan grading'!$B:$B,$B12),IF($C12="romain",SUMIFS('romain grading'!H:H,'romain grading'!$A:$A,$A12,'romain grading'!$B:$B,$B12),SUMIFS('nishita grading'!H:H,'nishita grading'!$A:$A,$A12,'nishita grading'!$B:$B,$B12))) | I12: =IF($C12="faizan",SUMIFS('faizan grading'!I:I,'faizan grading'!$A:$A,$A12,'faizan grading'!$B:$B,$B12),IF($C12="romain",SUMIFS('romain grading'!I:I,'romain grading'!$A:$A,$A12,'romain grading'!$B:$B,$B12),SUMIFS('nishita grading'!I:I,'nishita grading'!$A:$A,$A12,'nishita grading'!$B:$B,$B12))) | J12: =IF($C12="faizan",SUMIFS('faizan grading'!J:J,'faizan grading'!$A:$A,$A12,'faizan grading'!$B:$B,$B12),IF($C12="romain",SUMIFS('romain grading'!J:J,'romain grading'!$A:$A,$A12,'romain grading'!$B:$B,$B12),SUMIFS('nishita grading'!J:J,'nishita grading'!$A:$A,$A12,'nishita grading'!$B:$B,$B12))) | K12: =IF($C12="faizan",SUMIFS('faizan grading'!K:K,'faizan grading'!$A:$A,$A12,'faizan grading'!$B:$B,$B12),IF($C12="romain",SUMIFS('romain grading'!K:K,'romain grading'!$A:$A,$A12,'romain grading'!$B:$B,$B12),SUMIFS('nishita grading'!K:K,'nishita grading'!$A:$A,$A12,'nishita grading'!$B:$B,$B12))) | L12: =IF($C12="faizan",SUMIFS('faizan grading'!L:L,'faizan grading'!$A:$A,$A12,'faizan grading'!$B:$B,$B12),IF($C12="romain",SUMIFS('romain grading'!L:L,'romain grading'!$A:$A,$A12,'romain grading'!$B:$B,$B12),SUMIFS('nishita grading'!L:L,'nishita grading'!$A:$A,$A12,'nishita grading'!$B:$B,$B12))) | M12: =IF($C12="faizan",SUMIFS('faizan grading'!M:M,'faizan grading'!$A:$A,$A12,'faizan grading'!$B:$B,$B12),IF($C12="romain",SUMIFS('romain grading'!M:M,'romain grading'!$A:$A,$A12,'romain grading'!$B:$B,$B12),SUMIFS('nishita grading'!M:M,'nishita grading'!$A:$A,$A12,'nishita grading'!$B:$B,$B12))) | N12: =IF($C12="faizan",SUMIFS('faizan grading'!N:N,'faizan grading'!$A:$A,$A12,'faizan grading'!$B:$B,$B12),IF($C12="romain",SUMIFS('romain grading'!N:N,'romain grading'!$A:$A,$A12,'romain grading'!$B:$B,$B12),SUMIFS('nishita grading'!N:N,'nishita grading'!$A:$A,$A12,'nishita grading'!$B:$B,$B12))) | O12: =IF($C12="faizan",SUMIFS('faizan grading'!O:O,'faizan grading'!$A:$A,$A12,'faizan grading'!$B:$B,$B12),IF($C12="romain",SUMIFS('romain grading'!O:O,'romain grading'!$A:$A,$A12,'romain grading'!$B:$B,$B12),SUMIFS('nishita grading'!O:O,'nishita grading'!$A:$A,$A12,'nishita grading'!$B:$B,$B12))) | P12: =IF($C12="faizan",SUMIFS('faizan grading'!P:P,'faizan grading'!$A:$A,$A12,'faizan grading'!$B:$B,$B12),IF($C12="romain",SUMIFS('romain grading'!P:P,'romain grading'!$A:$A,$A12,'romain grading'!$B:$B,$B12),SUMIFS('nishita grading'!P:P,'nishita grading'!$A:$A,$A12,'nishita grading'!$B:$B,$B12))) | Q12: =IF($C12="faizan",SUMIFS('faizan grading'!Q:Q,'faizan grading'!$A:$A,$A12,'faizan grading'!$B:$B,$B12),IF($C12="romain",SUMIFS('romain grading'!Q:Q,'romain grading'!$A:$A,$A12,'romain grading'!$B:$B,$B12),SUMIFS('nishita grading'!Q:Q,'nishita grading'!$A:$A,$A12,'nishita grading'!$B:$B,$B12))) | R12: =44-SUM(D12:Q12)
A13: cooperative | B13: 44 | C13: nishita | D13: =IF($C13="faizan",SUMIFS('faizan grading'!D:D,'faizan grading'!$A:$A,$A13,'faizan grading'!$B:$B,$B13),IF($C13="romain",SUMIFS('romain grading'!D:D,'romain grading'!$A:$A,$A13,'romain grading'!$B:$B,$B13),SUMIFS('nishita grading'!D:D,'nishita grading'!$A:$A,$A13,'nishita grading'!$B:$B,$B13))) | E13: =IF($C13="faizan",SUMIFS('faizan grading'!E:E,'faizan grading'!$A:$A,$A13,'faizan grading'!$B:$B,$B13),IF($C13="romain",SUMIFS('romain grading'!E:E,'romain grading'!$A:$A,$A13,'romain grading'!$B:$B,$B13),SUMIFS('nishita grading'!E:E,'nishita grading'!$A:$A,$A13,'nishita grading'!$B:$B,$B13))) | F13: =IF($C13="faizan",SUMIFS('faizan grading'!F:F,'faizan grading'!$A:$A,$A13,'faizan grading'!$B:$B,$B13),IF($C13="romain",SUMIFS('romain grading'!F:F,'romain grading'!$A:$A,$A13,'romain grading'!$B:$B,$B13),SUMIFS('nishita grading'!F:F,'nishita grading'!$A:$A,$A13,'nishita grading'!$B:$B,$B13))) | G13: =IF($C13="faizan",SUMIFS('faizan grading'!G:G,'faizan grading'!$A:$A,$A13,'faizan grading'!$B:$B,$B13),IF($C13="romain",SUMIFS('romain grading'!G:G,'romain grading'!$A:$A,$A13,'romain grading'!$B:$B,$B13),SUMIFS('nishita grading'!G:G,'nishita grading'!$A:$A,$A13,'nishita grading'!$B:$B,$B13))) | H13: =IF($C13="faizan",SUMIFS('faizan grading'!H:H,'faizan grading'!$A:$A,$A13,'faizan grading'!$B:$B,$B13),IF($C13="romain",SUMIFS('romain grading'!H:H,'romain grading'!$A:$A,$A13,'romain grading'!$B:$B,$B13),SUMIFS('nishita grading'!H:H,'nishita grading'!$A:$A,$A13,'nishita grading'!$B:$B,$B13))) | I13: =IF($C13="faizan",SUMIFS('faizan grading'!I:I,'faizan grading'!$A:$A,$A13,'faizan grading'!$B:$B,$B13),IF($C13="romain",SUMIFS('romain grading'!I:I,'romain grading'!$A:$A,$A13,'romain grading'!$B:$B,$B13),SUMIFS('nishita grading'!I:I,'nishita grading'!$A:$A,$A13,'nishita grading'!$B:$B,$B13))) | J13: =IF($C13="faizan",SUMIFS('faizan grading'!J:J,'faizan grading'!$A:$A,$A13,'faizan grading'!$B:$B,$B13),IF($C13="romain",SUMIFS('romain grading'!J:J,'romain grading'!$A:$A,$A13,'romain grading'!$B:$B,$B13),SUMIFS('nishita grading'!J:J,'nishita grading'!$A:$A,$A13,'nishita grading'!$B:$B,$B13))) | K13: =IF($C13="faizan",SUMIFS('faizan grading'!K:K,'faizan grading'!$A:$A,$A13,'faizan grading'!$B:$B,$B13),IF($C13="romain",SUMIFS('romain grading'!K:K,'romain grading'!$A:$A,$A13,'romain grading'!$B:$B,$B13),SUMIFS('nishita grading'!K:K,'nishita grading'!$A:$A,$A13,'nishita grading'!$B:$B,$B13))) | L13: =IF($C13="faizan",SUMIFS('faizan grading'!L:L,'faizan grading'!$A:$A,$A13,'faizan grading'!$B:$B,$B13),IF($C13="romain",SUMIFS('romain grading'!L:L,'romain grading'!$A:$A,$A13,'romain grading'!$B:$B,$B13),SUMIFS('nishita grading'!L:L,'nishita grading'!$A:$A,$A13,'nishita grading'!$B:$B,$B13))) | M13: =IF($C13="faizan",SUMIFS('faizan grading'!M:M,'faizan grading'!$A:$A,$A13,'faizan grading'!$B:$B,$B13),IF($C13="romain",SUMIFS('romain grading'!M:M,'romain grading'!$A:$A,$A13,'romain grading'!$B:$B,$B13),SUMIFS('nishita grading'!M:M,'nishita grading'!$A:$A,$A13,'nishita grading'!$B:$B,$B13))) | N13: =IF($C13="faizan",SUMIFS('faizan grading'!N:N,'faizan grading'!$A:$A,$A13,'faizan grading'!$B:$B,$B13),IF($C13="romain",SUMIFS('romain grading'!N:N,'romain grading'!$A:$A,$A13,'romain grading'!$B:$B,$B13),SUMIFS('nishita grading'!N:N,'nishita grading'!$A:$A,$A13,'nishita grading'!$B:$B,$B13))) | O13: =IF($C13="faizan",SUMIFS('faizan grading'!O:O,'faizan grading'!$A:$A,$A13,'faizan grading'!$B:$B,$B13),IF($C13="romain",SUMIFS('romain grading'!O:O,'romain grading'!$A:$A,$A13,'romain grading'!$B:$B,$B13),SUMIFS('nishita grading'!O:O,'nishita grading'!$A:$A,$A13,'nishita grading'!$B:$B,$B13))) | P13: =IF($C13="faizan",SUMIFS('faizan grading'!P:P,'faizan grading'!$A:$A,$A13,'faizan grading'!$B:$B,$B13),IF($C13="romain",SUMIFS('romain grading'!P:P,'romain grading'!$A:$A,$A13,'romain grading'!$B:$B,$B13),SUMIFS('nishita grading'!P:P,'nishita grading'!$A:$A,$A13,'nishita grading'!$B:$B,$B13))) | Q13: =IF($C13="faizan",SUMIFS('faizan grading'!Q:Q,'faizan grading'!$A:$A,$A13,'faizan grading'!$B:$B,$B13),IF($C13="romain",SUMIFS('romain grading'!Q:Q,'romain grading'!$A:$A,$A13,'romain grading'!$B:$B,$B13),SUMIFS('nishita grading'!Q:Q,'nishita grading'!$A:$A,$A13,'nishita grading'!$B:$B,$B13))) | R13: =44-SUM(D13:Q13)
... A91: clueless | B91: 17 | C91: nishita | D91: =IF($C91="faizan",SUMIFS('faizan grading'!D:D,'faizan grading'!$A:$A,$A91,'faizan grading'!$B:$B,$B91),IF($C91="romain",SUMIFS('romain grading'!D:D,'romain grading'!$A:$A,$A91,'romain grading'!$B:$B,$B91),SUMIFS('nishita grading'!D:D,'nishita grading'!$A:$A,$A91,'nishita grading'!$B:$B,$B91))) | E91: =IF($C91="faizan",SUMIFS('faizan grading'!E:E,'faizan grading'!$A:$A,$A91,'faizan grading'!$B:$B,$B91),IF($C91="romain",SUMIFS('romain grading'!E:E,'romain grading'!$A:$A,$A91,'romain grading'!$B:$B,$B91),SUMIFS('nishita grading'!E:E,'nishita grading'!$A:$A,$A91,'nishita grading'!$B:$B,$B91))) | F91: =IF($C91="faizan",SUMIFS('faizan grading'!F:F,'faizan grading'!$A:$A,$A91,'faizan grading'!$B:$B,$B91),IF($C91="romain",SUMIFS('romain grading'!F:F,'romain grading'!$A:$A,$A91,'romain grading'!$B:$B,$B91),SUMIFS('nishita grading'!F:F,'nishita grading'!$A:$A,$A91,'nishita grading'!$B:$B,$B91))) | G91: =IF($C91="faizan",SUMIFS('faizan grading'!G:G,'faizan grading'!$A:$A,$A91,'faizan grading'!$B:$B,$B91),IF($C91="romain",SUMIFS('romain grading'!G:G,'romain grading'!$A:$A,$A91,'romain grading'!$B:$B,$B91),SUMIFS('nishita grading'!G:G,'nishita grading'!$A:$A,$A91,'nishita grading'!$B:$B,$B91))) | H91: =IF($C91="faizan",SUMIFS('faizan grading'!H:H,'faizan grading'!$A:$A,$A91,'faizan grading'!$B:$B,$B91),IF($C91="romain",SUMIFS('romain grading'!H:H,'romain grading'!$A:$A,$A91,'romain grading'!$B:$B,$B91),SUMIFS('nishita grading'!H:H,'nishita grading'!$A:$A,$A91,'nishita grading'!$B:$B,$B91))) | I91: =IF($C91="faizan",SUMIFS('faizan grading'!I:I,'faizan grading'!$A:$A,$A91,'faizan grading'!$B:$B,$B91),IF($C91="romain",SUMIFS('romain grading'!I:I,'romain grading'!$A:$A,$A91,'romain grading'!$B:$B,$B91),SUMIFS('nishita grading'!I:I,'nishita grading'!$A:$A,$A91,'nishita grading'!$B:$B,$B91))) | J91: =IF($C91="faizan",SUMIFS('faizan grading'!J:J,'faizan grading'!$A:$A,$A91,'faizan grading'!$B:$B,$B91),IF($C91="romain",SUMIFS('romain grading'!J:J,'romain grading'!$A:$A,$A91,'romain grading'!$B:$B,$B91),SUMIFS('nishita grading'!J:J,'nishita grading'!$A:$A,$A91,'nishita grading'!$B:$B,$B91))) | K91: =IF($C91="faizan",SUMIFS('faizan grading'!K:K,'faizan grading'!$A:$A,$A91,'faizan grading'!$B:$B,$B91),IF($C91="romain",SUMIFS('romain grading'!K:K,'romain grading'!$A:$A,$A91,'romain grading'!$B:$B,$B91),SUMIFS('nishita grading'!K:K,'nishita grading'!$A:$A,$A91,'nishita grading'!$B:$B,$B91))) | L91: =IF($C91="faizan",SUMIFS('faizan grading'!L:L,'faizan grading'!$A:$A,$A91,'faizan grading'!$B:$B,$B91),IF($C91="romain",SUMIFS('romain grading'!L:L,'romain grading'!$A:$A,$A91,'romain grading'!$B:$B,$B91),SUMIFS('nishita grading'!L:L,'nishita grading'!$A:$A,$A91,'nishita grading'!$B:$B,$B91))) | M91: =IF($C91="faizan",SUMIFS('faizan grading'!M:M,'faizan grading'!$A:$A,$A91,'faizan grading'!$B:$B,$B91),IF($C91="romain",SUMIFS('romain grading'!M:M,'romain grading'!$A:$A,$A91,'romain grading'!$B:$B,$B91),SUMIFS('nishita grading'!M:M,'nishita grading'!$A:$A,$A91,'nishita grading'!$B:$B,$B91))) | N91: =IF($C91="faizan",SUMIFS('faizan grading'!N:N,'faizan grading'!$A:$A,$A91,'faizan grading'!$B:$B,$B91),IF($C91="romain",SUMIFS('romain grading'!N:N,'romain grading'!$A:$A,$A91,'romain grading'!$B:$B,$B91),SUMIFS('nishita grading'!N:N,'nishita grading'!$A:$A,$A91,'nishita grading'!$B:$B,$B91))) | O91: =IF($C91="faizan",SUMIFS('faizan grading'!O:O,'faizan grading'!$A:$A,$A91,'faizan grading'!$B:$B,$B91),IF($C91="romain",SUMIFS('romain grading'!O:O,'romain grading'!$A:$A,$A91,'romain grading'!$B:$B,$B91),SUMIFS('nishita grading'!O:O,'nishita grading'!$A:$A,$A91,'nishita grading'!$B:$B,$B91))) | P91: =IF($C91="faizan",SUMIFS('faizan grading'!P:P,'faizan grading'!$A:$A,$A91,'faizan grading'!$B:$B,$B91),IF($C91="romain",SUMIFS('romain grading'!P:P,'romain grading'!$A:$A,$A91,'romain grading'!$B:$B,$B91),SUMIFS('nishita grading'!P:P,'nishita grading'!$A:$A,$A91,'nishita grading'!$B:$B,$B91))) | Q91: =IF($C91="faizan",SUMIFS('faizan grading'!Q:Q,'faizan grading'!$A:$A,$A91,'faizan grading'!$B:$B,$B91),IF($C91="romain",SUMIFS('romain grading'!Q:Q,'romain grading'!$A:$A,$A91,'romain grading'!$B:$B,$B91),SUMIFS('nishita grading'!Q:Q,'nishita grading'!$A:$A,$A91,'nishita grading'!$B:$B,$B91))) | R91: =44-SUM(D91:Q91)

Sheet faizan grading
A1: persona type | B1: transcript number | C1: transcript | D1: 1.1.A | E1: 1.1.B | F1: 1.1.C | G1: 1.2.A | H1: 1.2.B | I1: 1.3.A | J1: 1.3.B | K1: 1.3.C | L1: 2.1.A | M1: 2.2.A | N1: 2.2.B | O1: 3.1.A | P1: 3.2.A | Q1: 3.2.B | R1: total score
